[2024-04-24T09:35:53.686+0800] {local_task_job_runner.py:120} INFO - ::group::Pre task execution logs
[2024-04-24T09:35:53.811+0800] {taskinstance.py:2073} INFO - Dependencies all met for dep_context=non-requeueable deps ti=<TaskInstance: 3107_project.clean_linkedin_jobs__5 manual__2024-04-23T17:53:46.323504+00:00 [queued]>
[2024-04-24T09:35:53.836+0800] {taskinstance.py:2073} INFO - Dependencies all met for dep_context=requeueable deps ti=<TaskInstance: 3107_project.clean_linkedin_jobs__5 manual__2024-04-23T17:53:46.323504+00:00 [queued]>
[2024-04-24T09:35:53.838+0800] {taskinstance.py:2303} INFO - Starting attempt 1 of 1
[2024-04-24T09:35:53.894+0800] {taskinstance.py:2327} INFO - Executing <Task(_PythonDecoratedOperator): clean_linkedin_jobs__5> on 2024-04-23 17:53:46.323504+00:00
[2024-04-24T09:35:53.901+0800] {standard_task_runner.py:63} INFO - Started process 1072130 to run task
[2024-04-24T09:35:53.905+0800] {standard_task_runner.py:90} INFO - Running: ['airflow', 'tasks', 'run', '3107_project', 'clean_linkedin_jobs__5', 'manual__2024-04-23T17:53:46.323504+00:00', '--job-id', '411', '--raw', '--subdir', 'DAGS_FOLDER/project_main_CCA23_4.py', '--cfg-path', '/tmp/tmpf0p_scc0']
[2024-04-24T09:35:53.907+0800] {standard_task_runner.py:91} INFO - Job 411: Subtask clean_linkedin_jobs__5
[2024-04-24T09:35:54.033+0800] {task_command.py:426} INFO - Running <TaskInstance: 3107_project.clean_linkedin_jobs__5 manual__2024-04-23T17:53:46.323504+00:00 [running]> on host DESKTOP-COSTHAS.
[2024-04-24T09:35:54.319+0800] {taskinstance.py:2644} INFO - Exporting env vars: AIRFLOW_CTX_DAG_OWNER='airflow' AIRFLOW_CTX_DAG_ID='3107_project' AIRFLOW_CTX_TASK_ID='clean_linkedin_jobs__5' AIRFLOW_CTX_EXECUTION_DATE='2024-04-23T17:53:46.323504+00:00' AIRFLOW_CTX_TRY_NUMBER='1' AIRFLOW_CTX_DAG_RUN_ID='manual__2024-04-23T17:53:46.323504+00:00'
[2024-04-24T09:35:54.324+0800] {taskinstance.py:430} INFO - ::endgroup::
[2024-04-24T09:35:54.351+0800] {taskinstance.py:441} INFO - ::group::Post task execution logs
[2024-04-24T09:35:54.355+0800] {taskinstance.py:2890} ERROR - Task failed with exception
Traceback (most recent call last):
  File "/mnt/c/Users/Jason/Desktop/IS3107/is3107_DataEngineering/.venv/lib/python3.8/site-packages/airflow/models/taskinstance.py", line 465, in _execute_task
    result = _execute_callable(context=context, **execute_callable_kwargs)
  File "/mnt/c/Users/Jason/Desktop/IS3107/is3107_DataEngineering/.venv/lib/python3.8/site-packages/airflow/models/taskinstance.py", line 432, in _execute_callable
    return execute_callable(context=context, **execute_callable_kwargs)
  File "/mnt/c/Users/Jason/Desktop/IS3107/is3107_DataEngineering/.venv/lib/python3.8/site-packages/airflow/models/baseoperator.py", line 400, in wrapper
    return func(self, *args, **kwargs)
  File "/mnt/c/Users/Jason/Desktop/IS3107/is3107_DataEngineering/.venv/lib/python3.8/site-packages/airflow/decorators/base.py", line 265, in execute
    return_value = super().execute(context)
  File "/mnt/c/Users/Jason/Desktop/IS3107/is3107_DataEngineering/.venv/lib/python3.8/site-packages/airflow/models/baseoperator.py", line 400, in wrapper
    return func(self, *args, **kwargs)
  File "/mnt/c/Users/Jason/Desktop/IS3107/is3107_DataEngineering/.venv/lib/python3.8/site-packages/airflow/operators/python.py", line 235, in execute
    return_value = self.execute_callable()
  File "/mnt/c/Users/Jason/Desktop/IS3107/is3107_DataEngineering/.venv/lib/python3.8/site-packages/airflow/operators/python.py", line 252, in execute_callable
    return self.python_callable(*self.op_args, **self.op_kwargs)
  File "/mnt/c/Users/Jason/Desktop/IS3107/is3107_DataEngineering/dags/project_main_CCA23_4.py", line 178, in clean_linkedin_jobs
    data['Job_txt'] = data['Job_txt'].apply(lambda x : x.split('Report this job')[1].replace("â€™", "'"))
  File "/mnt/c/Users/Jason/Desktop/IS3107/is3107_DataEngineering/.venv/lib/python3.8/site-packages/pandas/core/series.py", line 4630, in apply
    return SeriesApply(self, func, convert_dtype, args, kwargs).apply()
  File "/mnt/c/Users/Jason/Desktop/IS3107/is3107_DataEngineering/.venv/lib/python3.8/site-packages/pandas/core/apply.py", line 1025, in apply
    return self.apply_standard()
  File "/mnt/c/Users/Jason/Desktop/IS3107/is3107_DataEngineering/.venv/lib/python3.8/site-packages/pandas/core/apply.py", line 1076, in apply_standard
    mapped = lib.map_infer(
  File "pandas/_libs/lib.pyx", line 2834, in pandas._libs.lib.map_infer
  File "/mnt/c/Users/Jason/Desktop/IS3107/is3107_DataEngineering/dags/project_main_CCA23_4.py", line 178, in <lambda>
    data['Job_txt'] = data['Job_txt'].apply(lambda x : x.split('Report this job')[1].replace("â€™", "'"))
AttributeError: 'float' object has no attribute 'split'
[2024-04-24T09:35:54.418+0800] {taskinstance.py:1205} INFO - Marking task as FAILED. dag_id=3107_project, task_id=clean_linkedin_jobs__5, execution_date=20240423T175346, start_date=20240424T013553, end_date=20240424T013554
[2024-04-24T09:35:54.477+0800] {standard_task_runner.py:110} ERROR - Failed to execute job 411 for task clean_linkedin_jobs__5 ('float' object has no attribute 'split'; 1072130)
[2024-04-24T09:35:54.506+0800] {local_task_job_runner.py:240} INFO - Task exited with return code 1
[2024-04-24T09:35:54.557+0800] {taskinstance.py:3482} INFO - 0 downstream tasks scheduled from follow-on schedule check
[2024-04-24T09:35:54.564+0800] {local_task_job_runner.py:222} INFO - ::endgroup::
